Workbook

Sheet General
Q1: #VALUE! | AU1: #VALUE!
A3: Folio Interno de Solicitud | B3: Fecha Ingreso de Solicitud | C3: Semaforo | D3: Origen de Recurso | E3: Dependencia | F3: Centro de Costo | G3: Capitulo | H3: Concepto del Gasto | I3: Giro o Partida | J3: Tipo Contracion | K3: Valor del Estudio de Mercado | L3: Estatus del Estudio de Mercado | M3: Estado | N3: Tipo de Solicitud: | O3: Monto SABYS | P3: Descripción del bien o servicio de acuerdo a la solicitud | Q3: Contratacion Plurianual | R3: Monto 2026 | S3: Monto 2027 | T3: Monto 2028 | U3: Monto 2029 | V3: Folio de Solicitud de Adquisición. (CA) | W3: Fecha de Liberación de Estudio de Mercado | X3: Nombre de Testigo Social (N/A,Nombre) | Y3: Tipo de gasto: | Z3: Fuente de financiamiento: | AA3: Importe de Suficiencia Presupuestal | AB3: Oficio de Suficiencia | AC3: Clave de Verificación | AD3: Descripción de la Clave de Verificación | AE3: Unidad de Medida | AF3: ¿Es contrato abierto? | AG3: ¿Es consolidado? | AH3: Modalidad del Procedimiento Adquisitivo | AI3: Dictamen de Procedencia(Pdf) | AJ3: Responsable del Procedimiento | AK3: No. de procedimiento | AL3: Convocatoria y/o Invitacion (URL) | AM3: Medio de Publicación: | AN3: Fecha de Junta de Aclaración: | AO3: Hora de Junta de Aclaración: | AP3: Fecha de Presentación y Apertura de Proposiciones: | AQ3: Hora de Presentación y Apertura de Proposiciones: | AR3: Fecha de Sesión del Comité de Adquisiciones y Servicios para Análisis Cualitativ | AS3: Hora de Sesión del Comité de Adquisiciones y Servicios para Análisis Cualitativo | AT3: Fecha de Contra Oferta: | AU3: Hora de Contra Oferta: | AV3: Fecha de Dictaminación de Adjudicación del Comité: | AW3: Hora de de Dictaminación de Adjudicación del Comité: | AX3: Fecha de Fallo: | AY3: Hora de Fallo: | AZ3: Nombre o Razón Social | BA3: RFC | BB3: Representación Legal | BC3: Cargar Documento (Pdf) | BD3: Monto Total Adjudicación con IVA | BE3: Numero de Contrato: | BF3: Inicio de Vigencia: | BG3: Termino de Vigencia: | BH3: Publicación del Testimonio del Testigo Social: | BI3: REMANENTE(Suf.Presupuestal | BJ3: Nombre del Responsable del Procedimiento | BK3: Comentarios | BL3: Estatus | BM3: Columna1
A4: F-0001-2026 | B4: 46063 | C4: Concluido | D4: Federal | E4: Secretaría de la Contraloría | F4: Coordinación Administrativa (21800005000000S) | G4: 3000 Servicios generales | H4: 3400 – Servicios Financieros, Bancarios y Comerciales | I4: 3451 Seguros y fianzas | J4: LPNP | K4: 1,234,097.32 | L4: Concluido | M4: Adjudicado | N4: Servicio- Contratacion de servicios generales | O4: 1234097.3 | P4: ASEGURAMIENTO VEHICULAR | Q4: NO | V4: F-SC-001-2026 | W4: 46076 | X4: N/A | Y4: GC-Gasto Corriente | Z4: 15000000 - Recursos federales | AA4: 1234097.32 | AB4: https://gobedomex-my.sharepoint.com/my?id=%2Fpersonal%2Fcoordtic%5Fom%5Fedomex%5Fgob%5Fmx%2FDocuments%2FDGRM%20Archivos%2F1%2FDICTAMEN%20DE%20PROCEDENCIA%20ADP%2D001%2D202618%2D02%2D2026%2D165332%2Epdf&parent=%2Fpersonal%2Fcoordtic%5Fom%5Fedomex%5Fgob%5Fmx%2FDocuments%2FDGRM%20Archivos%2F1&ga=1 | AC4: 34501-0010 | AD4: ASEGURAMIENTO VEHICULAR | AE4: SERVICIO | AF4: No | AG4: No | AH4: Adjudicación Directa electrónica | AK4: AA-74-058-915002994-N-1-2026 | AL4: https://comprasmx.buengobierno.gob.mx/contrataciones/#/procedimientos/detalle-ad-sc/4c614d2c-2a7b-68db-e063-a61200a9409b | AM4: Electrónico - COMPRAMEX | AP4: 46087 | AQ4: 0.45833333 | AX4: 46087 | AY4: 0.54166667 | AZ4: Quálitas Compañía de Seguros, S.A. de C.V. | BA4: QCS931209G49 | BD4: 1195384 | BE4: CASF/001/2026 | BF4: 46087 | BG4: 46387 | BH4: N/A | BI4: 38713.33 | BJ4: Dirección de Procedimientos Adquisitivos "B" | BL4: Adjudicado | BM4: 1
A5: F-0002-2026 | B5: 46106 | C5: Concluido | D5: Federal | E5: Secretaría de la Contraloría | F5: Coordinación Administrativa (21800005000000S) | G5: 2000 Materiales y Suministros | H5: 2600-COMBUSTIBLES, LUBRICANTES Y ADITIVOS. | I5: 2341 Combustibles, lubricantes, aditivos, carbón y derivados | J5: LPNP | K5: 3900000 | L5: Concluido | M5: Adjudicado | N5: Servicio- Contratacion de servicios generales | O5: 3900000 | P5: SUMINISTRO DE COMBUSTIBLE MEDIANTE MONEDEROS ELECTRÓNICOS EN LA MODALIDAD DE CONTRATO ABIERTO | Q5: NO | V5: F-SC-002-2026 | W5: 46105 | X5: N/A | Y5: GC-Gasto Corriente | Z5: ["15000000 - Recursos federales"] | AA5: 3900000 | AB5: https://gobedomex-my.sharepoint.com/personal/coordtic_om_edomex_gob_mx/Documents/Aplicaciones/Microsoft%20Forms/Sistema%20de%20Seguimiento%20(2)%201/N%C3%BAmero%20de%20Oficio%20de%20liberaci%C3%B3n%20de%20recursos/CERTIFICACI%C3%93N%20-%20MONEDEROS%20ELECTR%C3%93NICOS_ARTURO%20GOMEZ%20GALICIA.pdf | AC5: 33602-0008 | AD5: OTROS SERVICIOS COMERCIALES | AE5: SERVICIO | AF5: Si | AG5: No | AH5: Invitación Restringida electrónica | AK5: IA-74-058-915002994-N-2-2026 | AL5: https://comprasmx.buengobierno.gob.mx/sitiopublico/#/ | AM5: Electrónico - COMPRAMEX | AP5: 46128 | AQ5: 0.41666667 | AX5: 46129 | AY5: 0.70833333 | AZ5: EFECTIVALE, S. DE R.L. DE C.V. | BA5: EFE8908015L3 | BD5: 3900000 | BE5: CASF/002/2026 | BF5: 46129 | BG5: 46387 | BH5: N/A | BI5: 0 | BJ5: Dirección de Procedimientos Adquisitivos "B" | BL5: Adjudicado | BM5: 2
A6: F-0003-2026 | B6: 46149 | C6: Atrasado | D6: Federal | E6: Secretaría de la Contraloría | F6: Coordinación Administrativa (21800005000000S) | G6: 2000 Materiales y Suministros | H6: 2100 – Materiales de Administración, Emisión de Documentos y Artículos Oficiales | I6: 2111 Materiales y útiles de oficina | J6: CP | L6: En Proceso | M6: En Proceso | N6: Bien- Adquisición de materiales y suministros | O6: 100280 | P6: ADQUISICIÓN DE PAPEL BOND TAMAÑO CARTA | Q6: NO | BM6: 23
A7: F-0004-2026 | B7: 46149 | C7: Atrasado | D7: Federal | E7: Secretaría de la Contraloría | F7: Coordinación Administrativa (21800005000000S) | G7: 2000 Materiales y Suministros | H7: 2300 – Materias Primas y Materiales de Producción y Comercialización | I7: 2381 Mercancías para su comercialización en tiendas del sector público | J7: CP | L7: En Proceso | M7: En Proceso | N7: Bien- Adquisición de materiales y suministros | O7: 120770 | P7: ADQUISICIÓN DE MATERIALES, BIENES E INSUMOS REQUERIDOS POR EL LABORATORIO DE ANÁLISIS Y VERIFICACIÓN DE CLIDAD DE MATERIALES DE CONSTRUCCIÓN | Q7: NO | BM7: 32
A8: F-0005-2026 | B8: 46149 | C8: Atrasado | D8: Federal | E8: Secretaría de la Contraloría | F8: Coordinación Administrativa (21800005000000S) | G8: 3000 Servicios generales | H8: 3500 – Servicios de Instalación, Reparación, Mantenimiento y Conservación | I8: 3571 Reparación, instalación y mantenimiento de maquinaria, equipo industrial y diverso | J8: CP | L8: En Proceso | M8: En Proceso | N8: Servicio- Contratacion de servicios generales | O8: 80800 | P8: SERVICIO DE CALIBRACIÓN A LOS EQUIPOS ESPECIALIZADOS DEL LABORATORIO DE ANÁLISIS Y VERIFICACIÓN DE CALIDAD DE MATERIALES DE CONSTRUCCIÓN | Q8: NO | BM8: 4
A9: F-0006-2026 | B9: 46149 | C9: Atrasado | D9: Federal | E9: Secretaría de la Contraloría | F9: Coordinación Administrativa (21800005000000S) | G9: 3000 Servicios generales | H9: 3500 – Servicios de Instalación, Reparación, Mantenimiento y Conservación | I9: 3571 Reparación, instalación y mantenimiento de maquinaria, equipo industrial y diverso | J9: CP | L9: En Proceso | M9: En Proceso | N9: Servicio- Contratacion de servicios generales | O9: 178100 | P9: SERVICIO DE MANTENIMIENTO A LOS EQUIPOS ESPECIALIZADOS DEL LABORATORIO DE ANÁLISIS Y VERIFICACIÓN DE CALIDAD DE MATERIALES DE CONSTRUCCIÓN | Q9: NO | BM9: 10
A10: F-0007-2026 | B10: 46150 | C10: Rechazado | D10: Federal | E10: Consejería Jurídica | F10: Coordinación Administrativa (23300001000000S) | G10: 5000 Bienes muebles inmuebles e intangibles | H10: 5600 – Maquinaria, Otros Equipos y Herramientas | I10: 5631 Maquinaria y equipo de construcción | J10: LPNP | L10: Rechazado | M10: Rechazado | N10: Bien- Adquisición de materiales y suministros | O10: 4120000 | P10: ADQUISICIÓN DE MAQUINARIA Y EQUIPO DE CONSTRUCCIÓN (MINICARGADOR) | Q10: NO | BM10: 38
A11: S001 | B11: 46029 | C11: Concluido | D11: Estatal | E11: Consejería Jurídica | F11: Coordinación Administrativa (23300001000000S) | G11: 3000 Servicios generales | H11: 3800 – Servicios Oficiales | I11: 3821 Gastos de ceremonias oficiales y de orden social | J11: LPNP | K11: 2,257,873.33 | L11: Concluido | M11: Adjudicado | N11: Servicio- Contratacion de servicios generales | O11: 61641216 | P11: CARAVANAS ITINERANTES POR LA JUSTICIA SOCIAL | Q11: SI | R11: 78940488 | S11: 78940488 | T11: 78940488 | U11: 50234856 | V11: CA-0009-2026 | W11: 46058 | X11: LUIS MANUEL ENRÍQUEZ ESTÉVEZ | Y11: GC-Gasto Corriente | Z11: 11010101 - Ingresos propios del sector central | AA11: 264171179.61 | AC11: 3821103004 | AD11: "CARAVANAS ITINERANTES POR LA JUSTICIA SOCIAL." | AE11: SERVICIO | AF11: No | AG11: No | AH11: Licitación Publicación Presencial | AI11: N/A | AK11: LPNP-002-2026 | AL11: https://compramex.edomex.gob.mx/compramex/public/catalogosExternos/detalleConvocatoria.xhtml | AM11: Electrónico - COMPRAMEX | AN11: 46065 | AO11: 0.54166667 | AP11: 46071 | AQ11: 0.54166667 | AR11: 46073 | AS11: 0.58333333 | AT11: 46073 | AU11: 0.70833333 | AV11: 46073 | AX11: 46073 | AY11: 0.73958333 | AZ11: JAJMA, S. DE R.L. DE C.V. | BA11: JAJ050824G65 | BD11: 245583000 | BE11: CS/OPD/4/2026 | BF11: 46072 | BG11: 47361 | BH11: N/A | BI11: 18588180 | BJ11: DIRECCIÓN DE PROCEDIMIENTOS ADQUISITIVOS DEL SECTOR AUXILIAR Y APOYO INTERSECTORIAL | BL11: Adjudicado | BM11: 7
A12: S002 | B12: 46030 | C12: Concluido | D12: Estatal | E12: Consejería Jurídica | F12: Coordinación Administrativa (23300001000000S) | G12: 3000 Servicios generales | H12: 3700 – Servicios de Traslado y Viáticos | I12: 3791 Otros servicios de traslado y hospedaje | K12: 1,003.27 | L12: Concluido | M12: Concluido | N12: Servicio- Contratacion de servicios generales | O12: 0 | P12: SERVICIO DE ESTACIONAMIENTO PARA LA CONSEJERÍA JURÍDICA | Q12: NO | BM12: 44
A13: S003 | B13: 46031 | C13: Rechazado | D13: Estatal | E13: Secretaría del Agua | F13: Coordinación Administrativa (23200002000000S) | G13: 5000 Bienes muebles inmuebles e intangibles | H13: 5100 – Mobiliario y Equipo de Administración | I13: 5111 Muebles y Enceres | J13: IRP | K13: 0 | L13: Rechazado | M13: Rechazado | N13: Bien- Adquisición de materiales y suministros | O13: 1500000 | P13: ARCHIVERO ESCRITORIO EJECUTIVO ESCRITORIO OPERATIVO SILLA EJECUTIVA SILLA SECRETARIAL ARCHIVERO ANAQUELES LIBRERO MESA OPERATIVA MESA DE TRABAJO MESA DE JUNTAS DISPENSADOR DE AGUA PERCHERO | Q13: NO | BM13: 46
A14: S004 | B14: 46032 | C14: Rechazado | D14: Estatal | E14: Secretaría del Agua | F14: Coordinación Administrativa (23200002000000S) | G14: 4000 Transferencias asignaciones subsidios y otras ayudas | H14: 4200 – Transferencias al Resto del Sector Público | I14: 4242 Donativos a municipios | K14: 0 | L14: Rechazado | M14: Rechazado | N14: Bien- Adquisición de materiales y suministros | O14: 0 | P14: TUBERÍA DE 50.8 MILÍMETROS PARA EL PROGRAMA EMERGENTE PARA MEJORA DE INFRAESTRUCTURA EN REDES DE DISTRIBUCIÓN TUBERÍA DE 101.6 MILÍMETROS PARA EL PROGRAMA EMERGENTE PARA MEJORA DE INFRAESTRUCTURA EN REDES DE DISTRIBUCIÓN TUBERÍA DE 152.4 MILÍMETROS PARA EL PROGRAMA EMERGENTE PARA MEJORA DE INFRAESTRUCTURA EN REDES DE DISTRIBUCIÓN | Q14: NO | BM14: 12
A15: S005 | B15: 46033 | C15: Rechazado | D15: Estatal | E15: Secretaría del Agua | F15: Coordinación Administrativa (23200002000000S) | G15: 4000 Transferencias asignaciones subsidios y otras ayudas | H15: 4200 – Transferencias al Resto del Sector Público | I15: 4242 Donativos a municipios | K15: 0 | L15: Rechazado | M15: Rechazado | N15: Bien- Adquisición de materiales y suministros | O15: 0 | P15: PAQUETE 1 INSTALACIÓN Y PUESTA EN MARCHA DE SISTEMAS DE CAPTADORES DE AGUA EN ESPACIÓS PÚBLICOS PAQUETE 2 INSTALACIÓN Y PUESTA EN MARCHA DE SISTEMAS DE CAPTADORES DE AGUA EN ESPACIÓS PÚBLICOS PAQUETE 3 INSTALACIÓN Y PUESTA EN MARCHA DE SISTEMAS DE CAPTADORES DE AGUA EN ESPACIÓS PÚBLICOS | Q15: NO | BM15: 13
A16: S006 | B16: 46034 | C16: Rechazado | D16: Estatal | E16: Secretaría del Agua | F16: Coordinación Administrativa (23200002000000S) | G16: 2000 Materiales y Suministros | H16: 2400 – Materiales y Artículos de Construcción y de Reparación | I16: 2411 Productos minerales no metálicos | K16: 0 | L16: Rechazado | M16: Rechazado | N16: Bien- Adquisición de materiales y suministros | O16: 0 | P16: PROGRAMA DE BAÑOS ECOLÓGICOS | Q16: NO | BM16: 14
A17: S007 | B17: 46035 | C17: Concluido | D17: Estatal | E17: Organismos OPDS | F17: Sistema para el Desarrollo Integral de la Familia del Estado de México 200C01000000000 | G17: 4000 Transferencias asignaciones subsidios y otras ayudas | H17: 4400 – Ayudas Sociales | I17: 4412 Despensas | J17: LPNP | K17: 2,302,790,324.14 | L17: Concluido | M17: Adjudicado | N17: Bien- Adquisición de materiales y suministros | O17: 2.3276237e+09 | P17: PAQUETE DE DESAYUNOS ESCOLARES FRÍOS PAQUETE DE ALIMENTOS DE DESAYUNOS ESCOLARES CALIENTES CANASTA DE PRODUCTOS ALIMENTICIOS | Q17: NO | V17: CA-0005-2026 | W17: 46042 | X17: Juan Manuel Ruano González | Y17: GC-Gasto Corriente | Z17: 14010101 - Ingresos por el cobro de derechos y venta de bienes y servicios | AA17: 2327623741.59 | AC17: "4412010004, 4412010005, 4412010006" | AD17: "PAQUETE DE DESAYUNOS ESCOLARES FRÍOS PAQUETE DE DESAYUNOS ESCOLARES CALIENTES CANASTA DE PRODUCTOS ALIMENTICIOS " | AE17: BIEN | AF17: Si | AG17: No | AH17: Invitación Restringida Presencial | AI17: N/A | AK17: IRP-001-2026 | AL17: https://compramex.edomex.gob.mx/compramex/public/catalogosExternos/procedimientsoAdquisitivos.xhtml | AM17: Electrónico - COMPRAMEX | AN17: 46086 | AO17: 0.41666667 | AP17: 46089 | AQ17: 0.41666667 | AR17: 46090 | AS17: 0.625 | AT17: 46090 | AU17: 0.64583333 | AV17: 46090 | AX17: 46090 | AY17: 0.65625 | AZ17: Despensas y Provisiones de Alimentos, S.A. DE C.V. | BA17: DPA0108013Y4 | BD17: 2.3210109e+09 | BE17: CB/OPD/3/2026 | BF17: 46091 | BG17: 46387 | BH17: https://recursosmateriales.edomex.gob.mx/testimonios | BI17: 6612856.5 | BJ17: Dirección de Procedimientos Adquisitivos del Sector Auxiliar y Apoyo Intersectorial | BL17: Adjudicado | BM17: 15
A18: S007-D | B18: 46035 | C18: Concluido | D18: Estatal | E18: Organismos OPDS | F18: Sistema para el Desarrollo Integral de la Familia del Estado de México 200C01000000000 | G18: 4000 Transferencias asignaciones subsidios y otras ayudas | H18: 4400 – Ayudas Sociales | I18: 4412 Despensas | J18: LPNP | K18: 2,302,790,324.14 | L18: Concluido | M18: Desierta | N18: Bien- Adquisición de materiales y suministros | O18: 2.3276237e+09 | P18: PAQUETE DE DESAYUNOS ESCOLARES FRÍOS PAQUETE DE ALIMENTOS DE DESAYUNOS ESCOLARES CALIENTES CANASTA DE PRODUCTOS ALIMENTICIOS | Q18: NO | V18: CA-0005-2026 | W18: 46042 | X18: Juan Manuel Ruano González | Y18: GC-Gasto Corriente | Z18: 14010101 - Ingresos por el cobro de derechos y venta de bienes y servicios | AA18: 2327623741.59 | AC18: "4412010004, 4412010005, 4412010006" | AD18: "PAQUETE DE DESAYUNOS ESCOLARES FRÍOS PAQUETE DE DESAYUNOS ESCOLARES CALIENTES CANASTA DE PRODUCTOS ALIMENTICIOS " | AE18: BIEN | AF18: Si | AG18: No | AH18: Licitación Publicación Presencial | AI18: N/A | AK18: LPNP-001-2026 | AL18: https://compramex.edomex.gob.mx/compramex/public/catalogosExternos/detalleConvocatoria.xhtml | AM18: Electrónico - COMPRAMEX | AN18: 46065 | AO18: 0.41666667 | AP18: 46071 | AQ18: 0.41666667 | AR18: 46079 | AS18: 0.58333333 | AT18: 46079 | AU18: 0.66666667 | AV18: 46079 | AX18: 46079 | AY18: 0.6875 | AZ18: DESPENSAS Y PROVISIONES DE ALIMENTOS, S.A. DE C.V. | BA18: DPA0108013Y4 | BD18: 0 | BE18: Desierto | BH18: Desierto | BI18: 0 | BJ18: DIRECCIÓN DE PROCEDIMIENTOS ADQUISITIVOS DEL SECTOR AUXILIAR Y APOYO INTERSECTORIAL | BK18: NO CONTRAOFERTO | BL18: Desierta | BM18: 11
A19: S008 | B19: 46036 | C19: Concluido | D19: Estatal | E19: Secretaría de Seguridad | F19: Coordinación Administrativa | G19: 3000 Servicios generales | H19: 3100 – Servicios Básicos | I19: 3191 Servicios de telecomunicación especializados | J19: LPNP | K19: 331,113,054.70 | L19: Concluido | M19: Adjudicado | N19: Servicio- Contratacion de servicios generales | O19: 3.4135366e+08 | P19: SISTEMA INTEGRAL DE DISPOSITIVOS DE MONITOREO ELECTRONICO (BRAZALETES) | Q19: NO | V19: CA-0004-2026 | W19: 46045 | X19: NO APLICA | Y19: GC-Gasto Corriente | Z19: 11010101 - Ingresos propios del sector central | AA19: 331108374.96 | AC19: 3191012677 | AD19: SISTEMA INTEGRAL DE DISPOSITIVOS DE MONITOREO ELECTRÓNICO (BRAZALETES) | AE19: SERVICIO | AF19: Si | AG19: No | AH19: Adjudicación Directa Presencial | AI19: https://gobedomex-my.sharepoint.com/personal/coordtic_om_edomex_gob_mx/Documents/Aplicaciones/Microsoft%20Forms/Sistema%20de%20Seguimiento%20(2)%202/Pregunta/ADP-004-2026_ERANDI%20GUADALUPE%20AGA.pdf | AJ19: DIRECCIÓN DE PROCEDIMIENTOS ADQUISITIVOS DEL SECTOR AUXILIAR Y APOYO INTERSECTORIAL | AK19: ADP-004-2026 | AL19: https://compramex.edomex.gob.mx/compramex/public/catalogosExternos/procedimientsoAdquisitivos.xhtml | AM19: Invitación | AP19: 46052 | AQ19: 0.4375 | AR19: 46052 | AS19: 0.66666667 | AT19: 46052 | AU19: 0.72916667 | AV19: 46052 | AX19: 46052 | AY19: 0.73958333 | AZ19: PROMOTORA E INFRAESTRUCTURA GB, S.A. DE C.V. | BA19: PIG140711UQ7 | BB19: Poder Notarial, persona moral | BC19: https://gobedomex-my.sharepoint.com/personal/coordtic_om_edomex_gob_mx/Documents/Aplicaciones/Microsoft%20Forms/Sistema%20de%20Seguimiento%20(2)%202/Convocatoria%20de%20Bases%20yo%20Invitacion%20(PDF)/ADP-004-2026_ERANDI%20GUADALUPE%20AGA.pdf | BD19: 3.3110837e+08 | BE19: CS/OPD/3/2026 | BF19: 11355 | BG19: 46387 | BH19: N/A | BI19: 10245290 | BJ19: DIRECCIÓN DE PROCEDIMIENTOS ADQUISITIVOS DEL SECTOR AUXILIAR Y APOYO INTERSECTORIAL | BL19: Adjudicado | BM19: 19
A20: S009 | B20: 46037 | C20: Concluido | D20: Estatal | E20: Secretaría de Seguridad | F20: Coordinación Administrativa | G20: 3000 Servicios generales | H20: 3500 – Servicios de Instalación, Reparación, Mantenimiento y Conservación | I20: 3581 Servicios de lavandería, limpieza e higiene | J20: LPNP | K20: 613,312,275.00 | L20: Concluido | M20: Adjudicado | N20: Servicio- Contratacion de servicios generales | O20: 613312275 | P20: SERVICIO INTEGRAL DE LAVANDERIA, LIMPIEZA, DESINFECCION E HIGIENE | Q20: NO | V20: CA-0002-2026 | W20: 46045 | X20: NO APLICA | Y20: GC-Gasto Corriente | Z20: 11010101 - Ingresos propios del sector central | AA20: 613312172.55 | AC20: 3581132835 | AD20: SERVICIO INTEGRAL DE LAVANDERÍA LIMPIEZA, DESINFECCIÓN E HIGIENE | AE20: SERVICIO | AF20: Si | AG20: No | AH20: Adjudicación Directa Presencial | AI20: https://gobedomex-my.sharepoint.com/personal/coordtic_om_edomex_gob_mx/Documents/Aplicaciones/Microsoft%20Forms/Sistema%20de%20Seguimiento%20(2)%202/Pregunta/ADP-002-2026_ERANDI%20GUADALUPE%20AGA.pdf | AJ20: DIRECCIÓN DE PROCEDIMIENTOS ADQUISITIVOS DEL SECTOR AUXILIAR Y APOYO INTERSECTORIAL | AK20: ADP-003-2026 | AL20: https://gobedomex-my.sharepoint.com/personal/coordtic_om_edomex_gob_mx/Documents/Aplicaciones/Microsoft%20Forms/Sistema%20de%20Seguimiento%20(2)%202/Convocatoria%20de%20Bases%20yo%20Invitacion%20(PDF)/ADP-002-2026_ERANDI%20GUADALUPE%20AGA.pdf | AM20: Invitación | AP20: 46052 | AQ20: 0.41666667 | AR20: 46052 | AS20: 0.66666667 | AT20: 46052 | AU20: 0.70833333 | AV20: 46052 | AX20: 46052 | AY20: 0.71875 | AZ20: LA COSMOPOLITANA, S.A. DE C.V. | BA20: COS850425822 | BB20: Poder Notarial, persona moral | BC20: https://gobedomex-my.sharepoint.com/personal/coordtic_om_edomex_gob_mx/Documents/Aplicaciones/Microsoft%20Forms/Sistema%20de%20Seguimiento%20(2)%203/Pregunta/PODER_ERANDI%20GUADALUPE%20AGA%201.pdf | BD20: 6.1331217e+08 | BE20: CS/OPD/2/2026 | BF20: 46054 | BG20: 46387 | BH20: N/A | BI20: 102.45 | BJ20: DIRECCIÓN DE PROCEDIMIENTOS ADQUISITIVOS DEL SECTOR AUXILIAR Y APOYO INTERSECTORIAL | BL20: Adjudicado | BM20: 3
A21: S010 | B21: 46038 | C21: Concluido | D21: Estatal | E21: Secretaría de Seguridad | F21: Coordinación Administrativa | G21: 2000 Materiales y Suministros | H21: 2200 – Alimentos y Utensilios | I21: 2211 Productos alimenticios para personas | J21: LPNP | K21: 1,347,366,262.84 | L21: Concluido | M21: Adjudicado | N21: Bien- Adquisición de materiales y suministros | O21: 1.3473663e+09 | P21: SUMINISTRO DE VIVERES Y ALIMENTOS PARA CONSUMO HUMANO | Q21: NO | V21: CA-0003-2026 | W21: 46045 | X21: NO APLICA | Y21: GC-Gasto Corriente | Z21: 11010101 - Ingresos propios del sector central | AA21: 1347366262.84 | AC21: 2211011490 | AD21: SUMINISTRO DE VÍVERES Y ALIMENTOS PARA CONSUMO HUMANO | AE21: BIEN | AF21: Si | AG21: No | AH21: Adjudicación Directa Presencial | AI21: https://gobedomex-my.sharepoint.com/personal/coordtic_om_edomex_gob_mx/Documents/Aplicaciones/Microsoft%20Forms/Sistema%20de%20Seguimiento%20(2)%202/Pregunta/ADP-002-2026_ERANDI%20GUADALUPE%20AGA.pdf | AJ21: DIRECCIÓN DE PROCEDIMIENTOS ADQUISITIVOS DEL SECTOR AUXILIAR Y APOYO INTERSECTORIAL | AK21: ADP-002-2026 | AL21: https://gobedomex-my.sharepoint.com/personal/coordtic_om_edomex_gob_mx/Documents/Aplicaciones/Microsoft%20Forms/Sistema%20de%20Seguimiento%20(2)%202/Convocatoria%20de%20Bases%20yo%20Invitacion%20(PDF)/ADP-002-2026_ERANDI%20GUADALUPE%20AGA.pdf | AM21: Invitación | AP21: 46052 | AQ21: 0.39583333 | AR21: 46052 | AS21: 0.66666667 | AT21: 46052 | AU21: 0.6875 | AV21: 46052 | AX21: 46052 | AY21: 0.69791667 | AZ21: LA COSMOPOLITANA, S.A. DE C.V. | BA21: COS850425822 | BB21: Poder Notarial, persona moral | BC21: https://gobedomex-my.sharepoint.com/personal/coordtic_om_edomex_gob_mx/Documents/Aplicaciones/Microsoft%20Forms/Sistema%20de%20Seguimiento%20(2)%203/Pregunta/PODER_ERANDI%20GUADALUPE%20AGA.pdf | BD21: 1.3473663e+09 | BE21: CB/OPD/1/2026 | BF21: 46054 | BG21: 46387 | BH21: N/A | BI21: 0 | BJ21: DIRECCIÓN DE PROCEDIMIENTOS ADQUISITIVOS DEL SECTOR AUXILIAR Y APOYO INTERSECTORIAL | BL21: Adjudicado | BM21: 29
A22: S011 | B22: 46039 | C22: Concluido | D22: Estatal | E22: Secretaría de Cultura y Turismo | F22: Coordinación Administrativa | G22: 3000 Servicios generales | H22: 3800 – Servicios Oficiales | I22: 3841 Exposiciones y ferias | J22: IRP | K22: 1,220,900.00 | L22: Concluido | M22: Adjudicado | N22: Servicio- Contratacion de servicios generales | O22: 1288900 | P22: SERVICIO INTEGRAL PARA LA PARTICIPACION DEL ESTADO DE MÉXICO EN LA FERIA INTERNACIONAL DEL TURISMO FITUR 2026 | Q22: NO | V22: CA-0001-2026 | W22: 46035 | X22: NO APLICA | Y22: GC-Gasto Corriente | Z22: 11010101 - Ingresos propios del sector central | AA22: 1288900 | AB22: https://gobedomex-my.sharepoint.com/personal/coordtic_om_edomex_gob_mx/Documents/Aplicaciones/Microsoft%20Forms/Sistema%20de%20Seguimiento%20(2)%201/N%C3%BAmero%20de%20Oficio%20de%20liberaci%C3%B3n%20de%20recursos/Scanned-image14-01-2026-120958%20(1)_JAQUELINE%20CASTA%C3%91EDA.pdf | AC22: 3841010123 | AD22: SERVICIO INTEGRAL PARA LA PARTICIPACIÓN DEL ESTADO DE MÉXICO EN LA FERIA INTERNACIONAL DE TURISMO “FITUR” 2026 | AE22: SERVICIO | AF22: No | AG22: No | AH22: Adjudicación Directa Presencial | AI22: DICTAMEN DE PROCEDENCIA ADP-001-202618-02-2026-165332.pdf | AJ22: DIRECCIÓN DE PROCEDIMIENTOS ADQUISITIVOS DEL SECTOR AUXILIAR Y APOYO INTERSECTORIAL | AK22: ADP-001-2026 | AL22: https://compramex.edomex.gob.mx/compramex/public/catalogosExternos/detalleConvocatoria.xhtml | AM22: Invitación | AP22: 46038 | AQ22: 0.70833333 | AR22: 46041 | AS22: 0.39583333 | AT22: 46041 | AU22: 0.41666667 | AV22: 46041 | AX22: 46041 | AY22: 0.42708333 | AZ22: CREATIVIDAD Y ESPECTACULOS S.A DE C.V | BA22: CES0107171KA | BD22: 1220900 | BE22: CS/OPD/1/2026 | BF22: 46041 | BG22: 46048 | BH22: N/A | BI22: 68000 | BJ22: DIRECCIÓN DE PROCEDIMIENTOS ADQUISITIVOS DEL SECTOR AUXILIAR Y APOYO INTERSECTORIAL | BL22: Adjudicado | BM22: 31
A23: S012 | B23: 46040 | C23: Concluido | D23: Estatal | E23: Secretaría de Finanzas | F23: Coordinación Administrativa(20700002000000S) | G23: 3000 Servicios generales | H23: 3800 – Servicios Oficiales | I23: 3821 Gastos de ceremonias oficiales y de orden social | J23: IRP | K23: 157,690.40 | L23: Concluido | M23: Concluido | N23: Servicio- Contratacion de servicios generales | O23: 157690.4 | P23: SERVICIO DE ALIMENTOS | Q23: NO | BM23: 47
A24: S013 | B24: 46036 | C24: Rechazado | D24: Estatal | E24: Secretaría de las Mujeres | F24: Coordinación Administrativa | G24: 3000 Servicios generales | H24: 3990-Otros Servicios Generales | I24: 3992 Gastos y servicios menores | K24: 0 | L24: Rechazado | M24: Rechazado | N24: Servicio- Contratacion de servicios generales | O24: 0 | P24: SERVICIO DE SUMINISTRO DE GARRAFÓN DE AGUA | Q24: NO | BM24: 48
A25: S014 | B25: 46041 | C25: Rechazado | D25: Estatal | E25: Secretaría de las Mujeres | F25: Coordinación Administrativa | G25: 3000 Servicios generales | H25: 3300 – Servicios Profesionales, Científicos, Técnicos y Otros Servicios | I25: 3311 Asesorías asociadas a convenios o acuerdos | K25: 0 | L25: Rechazado | M25: Rechazado | N25: Servicio- Contratacion de servicios generales | O25: 0 | P25: ASESORÍA Y REVISIÓN DE LOS PROCESOS DE NÓMINA RELATIVOS AL PERSONAL POR CONTRATO INDIVIDUAL DE TRABAJO POR TIEMPO DETERMINADO | Q25: NO | BM25: 49
A26: S015 | B26: 46042 | C26: Rechazado | D26: Estatal | E26: Secretaría de las Mujeres | F26: Coordinación Administrativa | G26: 3000 Servicios generales | H26: 3700 – Servicios de Traslado y Viáticos | I26: 3791 Otros servicios de traslado y hospedaje | K26: 0 | L26: Rechazado | M26: Rechazado | N26: Servicio- Contratacion de servicios generales | O26: 0 | P26: SERVICIO DE ESTACIONAMIENTO | Q26: NO | BM26: 50
A27: S016 | B27: 46043 | C27: Rechazado | D27: Estatal | E27: Secretaría de las Mujeres | F27: Coordinación Administrativa | G27: 5000 Bienes muebles inmuebles e intangibles | H27: 5300 – Equipo e Instrumental Médico y de Laboratorio | I27: 5311 Equipo médico y de laboratorio | K27: 0 | L27: Rechazado | M27: Rechazado | N27: Bien- Adquisición de materiales y suministros | O27: 0 | P27: MESA DE EXPLORACIÓN ESTÁNDAR SILLA DE RUEDAS ANDADERA INDUSTRIAL PLEGABLE MULETAS AUXILIARES DE ALUMINIO BÁSCULA ELECTRÓNICA PARA BEBÉ | Q27: NO | BM27: 51
A28: S017 | B28: 46036 | C28: Rechazado | D28: Estatal | E28: Secretaría de las Mujeres | F28: Coordinación Administrativa | G28: 3000 Servicios generales | H28: 3500 – Servicios de Instalación, Reparación, Mantenimiento y Conservación | I28: 3571 Reparación, instalación y mantenimiento de maquinaria, equipo industrial y diverso | K28: 0 | L28: Rechazado | M28: Rechazado | N28: Servicio- Contratacion de servicios generales | O28: 0 | P28: MANTENIMIENTO PREVENTIVO Y CORRECTIVO PARA ELEVADOR DE LA SECRETARÍA DE LAS MUJERES | Q28: No | BM28: 52
A29: S018 | B29: 46044 | C29: Rechazado | D29: Estatal | E29: Secretaría de las Mujeres | F29: Coordinación Administrativa | G29: 3000 Servicios generales | H29: 3100 – Servicios Básicos | I29: 3121 Gas | K29: 0 | L29: Rechazado | M29: Rechazado | N29: Servicio- Contratacion de servicios generales | O29: 0 | P29: SUMINISTRO DE GAS L.P. PARA LOS CENTROS LIBRE DE LA SECRETARIA DE LAS MUJERES | Q29: NO | BM29: 53
A30: S019 | B30: 46045 | C30: Rechazado | D30: Estatal | E30: Secretaría de las Mujeres | F30: Coordinación Administrativa | G30: 2000 Materiales y Suministros | H30: 2500 – Productos Químicos, Farmacéuticos y de Laboratorio | I30: 2541 Materiales, accesorios y suministros médicos | K30: 0 | L30: Rechazado | M30: Rechazado | N30: Bien- Adquisición de materiales y suministros | O30: 0 | P30: NEBULIZADOR ULTRASÓNICO HOSPITALARIO KIT DE NEBULIZADOR PEDIÁTRICA KIT DE NEBULIZADOR ADULTO MONITOR DE SIGNOS VITALES PORTÁTIL | Q30: NO | BM30: 54
A31: S020 | B31: 46046 | C31: Rechazado | D31: Estatal | E31: Secretaría de las Mujeres | F31: Coordinación Administrativa | G31: 2000 Materiales y Suministros | H31: 2500 – Productos Químicos, Farmacéuticos y de Laboratorio | I31: 2531 Medicinas y productos farmacéuticos | K31: 0 | L31: Rechazado | M31: Rechazado | N31: Bien- Adquisición de materiales y suministros | O31: 0 | P31: VITAMINAS Y MINERALES GOMITAS LORATADINA 5 MILIGRAMOS JARABE LORATADINA 10 MILIGRAMOS TRAMADOL 37.5 MILIGRAMOS AMANTADINA, CLORFENAMINA Y PARACETAMOL SUSPENSIÓN INFANTIL DE 60 MILILITROS BUTILHIOSINA, PARACETAMOL, SOLUCIÓN EN GOTAS DE 20 MILILITROS LORATADINA, PARACETAMOL Y FENILEFRINA TABLETAS NAPROXENO CON PARACETAMOL SUPOSITORIOS NAPROXENO SÓDICO CON PARACETAMOL 100 MILILITROS PARACETAMOL SOLUCIÓN EN GOTAS 30 MILILITROS PARACETAMOL SOLUCIÓN INFANTIL 3.2 GRAMOS FRASCO 120 MILILITROS NAPROXENO CON PARACETAMOL TABLETAS SALBUTAMOL PARA NEBULIZAR SULFATO DE PLATA CREMA 1 G/100 G TARRO CON 30 G. DICLOFENACO GEL, TUBO DE 60 GRAMOS DICLOFENACO TABLETAS 100 MILIGRAMOS COMPLEJO B CON DICLOFENACO TABLETAS COMPLEJO B CON DICLOFENACO INYECTABLE 100,100,20,5,75 MG/3 ML. CAJA CON 3 ÁMPULAS DEXAMETASONA TABLETAS 4 MILIGRAMOS MICONAZOL EN CREMA AMBROXOL, SALBUTAMOL JARABE 120 MILILITROS NITROFURAZONA 0.2 G POMADA 85 G TUBO 85 G SALBUMATOL PARA INHALACIÓN ÁCIDO ACETILSALICÍLICO DE 500 MILIGRAMOS ANTIGRIPAL PARACETAMOL, CAFEINA, CLORHIDRATO DE FENILEFRINA MALEATO DE CLORFENAMINA 500/25/5/4 MG. CAJA CON 10 TAB. CLORFENAMINA COMPUESTA 500 MG PARACETAMOL TAB. CAJA CON 10 TAB. AMANTADINA/CLORFENAMINA/PARACETAMOL GOTAS PEDIÁTRICAS FRASCO CON 60 ML. HIOSCINA, PARACETAMOL 10/500 MG. CAJA CON 24 TAB TRAMADOL/PARACETAMOL CAJA CON 20 TABLETAS PARACETAMOL SOLUCIÓN PEDIÁTRICA FRASCO/GOTERO 15 ML 100 MG/1 ML. SOBRES DE SUERO ORAL POLVO SABOR MANZANA CAJA CON 100 SOBRES 28.3 G. CALCIO EFERVESCENTE SALBUTAMOL AEROSOL AMBROXOL /SALBUTAMOL JARABE (0,040/0,150 GRAMOS/ 100 MILILITROS) PARACETAMOL DE 500 MILIGRAMOS IODOPOVIDONA ANTISÉPTICO PARA PIEL Y MUCOSA 120 MILILITROS CLOTRIMAZOL, TUBO CON 20 GRAMOS OXIDO DE ZINC CREMA AMOXICILINA, ACIDO CLAVULÁNICO, SUSPENSIÓN DE 60 MILILITROS AMOXICILINA 500 MILIGRAMOS AMOXICILINA 7.5 GRAMOS (500 MILIGRAMOS/5 MILILITROS) COMPLEJO B TABLETAS DEXAMETASONA INYECTABLE DE 8 MILILITROS | Q31: NO | BM31: 55
A32: S021 | B32: 46047 | C32: Rechazado | D32: Estatal | E32: Secretaría de las Mujeres | F32: Coordinación Administrativa | G32: 2000 Materiales y Suministros | H32: 2700 – Vestuario, Blancos, Prendas de Protección y Artículos Deportivos | I32: 2721 Prendas de seguridad y protección personal | K32: 0 | L32: Rechazado | M32: Rechazado | N32: Bien- Adquisición de materiales y suministros | O32: 0 | P32: SILBATO PARA BRIGADISTA OVERIK DESECHABLE CUBREZAPATO LAMPARA MANOS LIBRES PARA COMBATIR INCENDIOS MOCHILA PARA HERRAMIENTAS CINTURON DE HERRAMIENTAS, CON BOLSA PARA HERRAMIENTAS TRAJE DE BOMBERO PORTAEXTINTOR PARA EXTINTOR DE 9 KILOS CINTA DELIMIRADORA AMARILLA CON NEGRO CINTA DELIMITADORA PROHIBIDO EL PASO CINTA DELIMITADORA PRECAUCIÓN DETECTOR DE HUMO CON ALARMA DETECTOR DE GAS NATURAL Y GAS L.P. BATA DE TRABAJO | Q32: NO | BM32: 56
A33: S022 | B33: 46048 | C33: Rechazado | D33: Estatal | E33: Secretaría de las Mujeres | F33: Coordinación Administrativa | G33: 2000 Materiales y Suministros | H33: 2500 – Productos Químicos, Farmacéuticos y de Laboratorio | I33: 2541 Materiales, accesorios y suministros médicos | K33: 0 | L33: Rechazado | M33: Rechazado | N33: Bien- Adquisición de materiales y suministros | O33: 0 | P33: CUBREBOCAS TIPO MASCARILLA 5 CAPAS KN95 CUBREBOCAS TRICAPA, CAJA BAUMANÓMETRO DIGITAL GLUCÓMETRO OXÍMETRO TORUNDA DE ALGODÓN VENDA ELÁSTICA DE 5 CENTÍMETROS AGUA OXIGENADA DE 480 MILILITROS ESTETOSCOPIO DOBLE SUMINISTROS PARA BOTIQUÍN ALCOHOL ETÍLICO DE 250 MILILITROS GUANTES DE LÁTEX SABANAS DESECHABLES AZUL PARA CAMILLA TERMÓMETRO DIGITAL TIPO PISTOLA VENDA ELÁSTICA DE 7.5 CENTÍMETROS BOTIQUÍN PORTÁTIL GASA ESTÉRIL DE 10 POR 10 CENTÍMETROS CINTA MICROPOROSA COLOR PIEL CINTA 5CM X 9.1 MT. VENDITAS TRANSPIEL SURTIDAS VENDA ELÁSTICA DE 10 CENTÍMETROS ABATELENGUAS COLLARÍN DE INMOVILIZACIÓN AJUSTABLE TIRAS REACTIVAS Y LANCETAS | Q33: NO | BM33: 16
A34: S023 | B34: 46049 | C34: Rechazado | D34: Estatal | E34: Secretaría de las Mujeres | F34: Coordinación Administrativa | G34: 2000 Materiales y Suministros | H34: 2700 – Vestuario, Blancos, Prendas de Protección y Artículos Deportivos | I34: 2721 Prendas de seguridad y protección personal | K34: 0 | L34: Rechazado | M34: Rechazado | N34: Bien- Adquisición de materiales y suministros | O34: 0 | P34: CHALECO DE SEGURIDAD CASCO PROTECTOR LENTES DE PROTECCIÓN GUANTE DE CARNAZA ZAPATO INDUSTRIAL CON CASQUILLO DIELÉCTRICO GUANTES PARA COMBATIENTE DE INCENDIO CINTURON FAJA ARNÉS DE SEGURIDAD ANTICAIDAS CON CINCO ANILLOS LÍNEA DE VIDA GUANTES DIELÉCTRICOS PROTECCIÓN HASTA 1000 V. | Q34: NO | BM34: 26
A35: S024 | B35: 46050 | C35: Concluido | D35: Estatal | E35: Oficialía Mayor | F35: Coordinación Administrativa (23400000030000S) | G35: 3000 Servicios generales | H35: 3200 – Servicios de Arrendamiento | I35: 3251 Arrendamiento de vehículos | J35: LPNP | K35: 59,918,597.64 | L35: Concluido | M35: Adjudicado | N35: Servicio- Contratacion de servicios generales | O35: 67808036 | P35: RENTA DE AUTOBUSES | Q35: NO | V35: CA-0007-2026 | W35: 46057 | X35: NO APLICA | Y35: GC-Gasto Corriente | Z35: 11010101 - Ingresos propios del sector central | AA35: 59918597.64 | AC35: 3251010060 | AD35: SERVICIO DE RENTA DE AUTOBUSES PARA EL TRASLADO DE PERSONAL. | AE35: SERVICIO | AF35: Si | AG35: No | AH35: Licitación Publicación Presencial | AI35: N/A | AK35: LPNP-004-2026 | AL35: https://compramex.edomex.gob.mx/compramex/public/catalogosExternos/detalleConvocatoria.xhtml | AM35: Electrónico - COMPRAMEX | AN35: 46066 | AO35: 0.5 | AP35: 46072 | AQ35: 0.41666667 | AR35: 46076 | AS35: 0.58333333 | AT35: 46076 | AU35: 0.69791667 | AV35: 46076 | AX35: 46076 | AY35: 0.71875 | AZ35: ENLACES TERRESTRES TURMAR, S. DE R.L. DE C.V. | BA35: ETT160825FP7 | BD35: 59918598 | BE35: CS/OPD/6/2026 | BF35: 46073 | BG35: 46387 | BH35: N/A | BI35: 0 | BJ35: DIRECCIÓN DE PROCEDIMIENTOS ADQUISITIVOS DEL SECTOR AUXILIAR Y APOYO INTERSECTORIAL | BL35: Adjudicado | BM35: 33
A36: S025 | B36: 46051 | C36: Concluido | D36: Estatal | E36: Secretaría de Bienestar | F36: Coordinación Administrativa | G36: 4000 Transferencias asignaciones subsidios y otras ayudas | H36: 4400 – Ayudas Sociales | I36: 4413 Gastos relacionados con actividades culturales, deportivas y de ayuda extraordinaria | J36: LPNP | K36: 388,157,000.00 | L36: Concluido | M36: Adjudicado | N36: Servicio- Contratacion de servicios generales | O36: 352850190 | P36: SERVICIO DE EMISIÓN DE TARJETAS PERSONALIZADAS QUE SIRVA COMO MEDIO DE ACCESO AL APOYO MONETARIO Y DE SERVICIOS QUE OTORGA EL PROGRAMA DE DESARROLLO SOCIAL "MUJERES CON BIENESTAR" | Q36: NO | V36: CA-0010-2026 | W36: 46059 | X36: LUIS MANUEL ENRÍQUEZ ESTÉVEZ | Y36: GC-Gasto Corriente | Z36: 15010114 - Ramo 28 | AA36: 388157000 | AC36: 4413011138 | AD36: SERVICIO DE EMISIÓN DE TARJETAS PERSONALIZADAS QUE SIRVA COMO MEDIO DE ACCESO AL APOYO MONETARIO Y DE SERVICIOS QUE OTORGA EL PROGRAMA DE DESARROLLO SOCIAL "MUJERES CON BIENESTAR". | AE36: SERVICIO | AF36: Si | AG36: No | AH36: Licitación Publicación Presencial | AI36: N/A | AK36: LPNP-005-2026 | AL36: https://compramex.edomex.gob.mx/compramex/public/catalogosExternos/detalleConvocatoria.xhtml | AM36: Electrónico - COMPRAMEX | AN36: 46066 | AO36: 0.41666667 | AP36: 46071 | AQ36: 0.66666667 | AR36: 46073 | AS36: 0.58333333 | AT36: 46073 | AU36: 0.66666667 | AV36: 46073 | AX36: 46073 | AY36: 0.6875 | AZ36: SERVICIOS BROXEL, S.A.P.I. DE C.V. | BA36: SBR130327HU9 | BD36: 352814000 | BE36: CS/OPD/5/2026 | BF36: 46072 | BG36: 46387 | BI36: 35343000 | BJ36: DIRECCIÓN DE PROCEDIMIENTOS ADQUISITIVOS DEL SECTOR AUXILIAR Y APOYO INTERSECTORIAL | BL36: Adjudicado | BM36: 34
A37: S026 | B37: 46052 | C37: Concluido | D37: Estatal | E37: Secretaría de Educación, Ciencia, Tecnología e Innovación | F37: Coordinación Administrativa | G37: 3000 Servicios generales | H37: 3800 – Servicios Oficiales | I37: 3821 Gastos de ceremonias oficiales y de orden social | J37: LPNP | K37: 3,993,939.17 | L37: Concluido | M37: Adjudicado | N37: Servicio- Contratacion de servicios generales | O37: 4000000 | P37: SERVICIO INTEGRAL PARA LA ORGANIZACIÓN Y EJECUCIÓN DE LA "PRESEA ESTADO DE MÉXICO" 2025 | Q37: NO | V37: CA-0006-2026 | W37: 46056 | X37: NO APLICA | Y37: GC-Gasto Corriente | Z37: 11010101 - Ingresos propios del sector central | AA37: 4000000 | AC37: 3821103007 | AD37: SERVICIO INTEGRAL PARA LA ORGANIZACIÓN Y EJECUCIÓN DE LA "PRESA ESTADO DE MÉXICO" 2025. | AE37: SERVICIO | AF37: No | AG37: No | AH37: Licitación Publica Nacional Presencial | AI37: N/A | AK37: LPNP-003-2026 | AL37: https://compramex.edomex.gob.mx/compramex/public/catalogosExternos/detalleConvocatoria.xhtml | AM37: Electrónico - COMPRAMEX | AN37: 46066 | AO37: 0.41666667 | AP37: 46071 | AQ37: 0.41666667 | AR37: 46073 | AS37: 0.58333333 | AT37: 46073 | AU37: 0.70833333 | AV37: 46073 | AX37: 46073 | AY37: 0.72916667 | AZ37: GREGORIA CUEVAS ALVIRDE | BA37: CUAG780429480 | BD37: 3823000 | BE37: CS/B/1/2026 | BF37: 46073 | BG37: 46083 | BH37: N/A | BI37: 170939.17 | BJ37: Orlando Gutiérrez Vilchis | BL37: Adjudicado | BM37: 5
A38: S027 | B38: 46053 | C38: Concluido | D38: Estatal | E38: Secretaría de Cultura y Turismo | F38: Coordinación Administrativa | G38: 3000 Servicios generales | H38: 3800 – Servicios Oficiales | I38: 3841 Exposiciones y ferias | J38: CP | K38: 576,666.76 | L38: Concluido | M38: Concluido | N38: Servicio- Contratacion de servicios generales | O38: 580000 | P38: SERVICIO INTEGRAL PARA LA "EXPO FERIA TEQUIXQUIAC 206" | Q38: NO | BM38: 17
A39: S028 | B39: 46054 | C39: Concluido | D39: Estatal | E39: Oficialía Mayor | F39: Coordinación Administrativa (23400000030000S) | G39: 3000 Servicios generales | H39: 3300 – Servicios Profesionales, Científicos, Técnicos y Otros Servicios | I39: 3341 Capacitación | J39: CP | K39: 392,354.01 | L39: Concluido | M39: Concluido | N39: Servicio- Contratacion de servicios generales | O39: 500000 | P39: ENTRENAMIENTO DE EXTINCIÓN CONTRA INCENDIOS (HELICOPTER AERIAL FIREFIGHTING TRAINING) | Q39: NO | BM39: 18
A40: S029 | B40: 46055 | C40: Concluido | D40: Estatal | E40: Secretaría de Salud | F40: Coordinación Administrativa ( 20800001000000S ) | G40: 3000 Servicios generales | H40: 3700 – Servicios de Traslado y Viáticos | I40: 3791 Otros servicios de traslado y hospedaje | J40: CP | K40: 965.51 | L40: Concluido | M40: Concluido | N40: Servicio- Contratacion de servicios generales | O40: 117000 | P40: SERVICIO DE ESTACIONAMIENTO | Q40: NO | BM40: 20
A41: S030 | B41: 46056 | C41: Concluido | D41: Estatal | E41: Oficialía Mayor | F41: Coordinación Administrativa (23400000030000S) | G41: 3000 Servicios generales | H41: 3200 – Servicios de Arrendamiento | I41: 3251 Arrendamiento de vehículos | J41: CP | K41: 580,000.00 | L41: Concluido | M41: Concluido | N41: Servicio- Contratacion de servicios generales | O41: 580000 | P41: SERVICIO DE RENTA DE AUTOBUSES PARA EL TRASLADO DEL PERSONAL. | Q41: NO | BM41: 21
...

Sheet Estudio de Mercado
A2: Folio Interno de Solicitud | B2: Fecha Ingreso de Solicitud | C2: Semaforo | D2: Origen de Recurso | E2: Dependencia | F2: Centro de Costo | G2: Capitulo | H2: Concepto del Gasto | I2: Giro o Partida | J2: Tipo Contracion | K2: Valor del Estudio de Mercado | L2: Estatus del Estudio de Mercado | M2: Estado | N2: Tipo de Solicitud: | O2: Monto SABYS | P2: Descripción del bien o servicio de acuerdo a la solicitud | Q2: Contratacion Plurianual | R2: Monto 2026 | S2: Monto 2027 | T2: Monto 2028 | U2: Monto 2029
A3: F-0001-2026 | B3: 46063 | C3: =IF(L3="Rechazado", "Rechazado", IF(L3="Concluido", "Concluido", IF(AND(L3="En Proceso", TODAY()<=WORKDAY(B3,15)), "En Tiempo", IF(L3="En Proceso", "Atrasado", "")))) -> Concluido | D3: Federal | E3: Secretaría de la Contraloría | F3: Coordinación Administrativa (21800005000000S) | G3: 3000 Servicios generales | H3: 3400 – Servicios Financieros, Bancarios y Comerciales | I3: 3451 Seguros y fianzas | J3: =IF(O3="","", IFERROR( IF(VALUE(SUBSTITUTE(SUBSTITUTE(TRIM(O3),"$",""),",",""))<=0,"", IF(VALUE(SUBSTITUTE(SUBSTITUTE(TRIM(O3),"$",""),",",""))<=580000,"CP", IF(VALUE(SUBSTITUTE(SUBSTITUTE(TRIM(O3),"$",""),",",""))<=1740000,"IRP","LPNP"))), "")) -> IRP | K3: 1,234,097.32 | L3: Concluido | M3: =IFERROR(IF(OR(VLOOKUP(A3,Adjudicacion!A:N,14,0)=0, VLOOKUP(A3,Adjudicacion!A:N,14,0)=""), L3, VLOOKUP(A3,Adjudicacion!A:N,14,0)), L3) -> Adjudicado | N3: Servicio- Contratacion de servicios generales | O3: 1234097.3 | P3: ASEGURAMIENTO VEHICULAR | Q3: NO
A4: F-0002-2026 | B4: 46106 | C4: =IF(L4="Rechazado", "Rechazado", IF(L4="Concluido", "Concluido", IF(AND(L4="En Proceso", TODAY()<=WORKDAY(B4,15)), "En Tiempo", IF(L4="En Proceso", "Atrasado", "")))) -> Concluido | D4: Federal | E4: Secretaría de la Contraloría | F4: Coordinación Administrativa (21800005000000S) | G4: 2000 Materiales y Suministros | H4: 2600-COMBUSTIBLES, LUBRICANTES Y ADITIVOS. | I4: 2341 Combustibles, lubricantes, aditivos, carbón y derivados | J4: =IF(O4="","", IFERROR( IF(VALUE(SUBSTITUTE(SUBSTITUTE(TRIM(O4),"$",""),",",""))<=0,"", IF(VALUE(SUBSTITUTE(SUBSTITUTE(TRIM(O4),"$",""),",",""))<=580000,"CP", IF(VALUE(SUBSTITUTE(SUBSTITUTE(TRIM(O4),"$",""),",",""))<=1740000,"IRP","LPNP"))), "")) -> LPNP | K4: 3900000 | L4: Concluido | M4: =IFERROR(IF(OR(VLOOKUP(A4,Adjudicacion!A:N,14,0)=0, VLOOKUP(A4,Adjudicacion!A:N,14,0)=""), L4, VLOOKUP(A4,Adjudicacion!A:N,14,0)), L4) -> Adjudicado | N4: Servicio- Contratacion de servicios generales | O4: 3900000 | P4: SUMINISTRO DE COMBUSTIBLE MEDIANTE MONEDEROS ELECTRÓNICOS EN LA MODALIDAD DE CONTRATO ABIERTO | Q4: NO
A5: F-0003-2026 | B5: 46149 | C5: =IF(L5="Rechazado", "Rechazado", IF(L5="Concluido", "Concluido", IF(AND(L5="En Proceso", TODAY()<=WORKDAY(B5,15)), "En Tiempo", IF(L5="En Proceso", "Atrasado", "")))) -> Atrasado | D5: Federal | E5: Secretaría de la Contraloría | F5: Coordinación Administrativa (21800005000000S) | G5: 2000 Materiales y Suministros | H5: 2100 – Materiales de Administración, Emisión de Documentos y Artículos Oficiales | I5: 2111 Materiales y útiles de oficina | J5: =IF(O5="","", IFERROR( IF(VALUE(SUBSTITUTE(SUBSTITUTE(TRIM(O5),"$",""),",",""))<=0,"", IF(VALUE(SUBSTITUTE(SUBSTITUTE(TRIM(O5),"$",""),",",""))<=580000,"CP", IF(VALUE(SUBSTITUTE(SUBSTITUTE(TRIM(O5),"$",""),",",""))<=1740000,"IRP","LPNP"))), "")) -> CP | L5: En Proceso | M5: =IFERROR(IF(OR(VLOOKUP(A5,Adjudicacion!A:N,14,0)=0, VLOOKUP(A5,Adjudicacion!A:N,14,0)=""), L5, VLOOKUP(A5,Adjudicacion!A:N,14,0)), L5) -> En Proceso | N5: Bien- Adquisición de materiales y suministros | O5: 100280 | P5: ADQUISICIÓN DE PAPEL BOND TAMAÑO CARTA | Q5: NO
A6: F-0004-2026 | B6: 46149 | C6: =IF(L6="Rechazado", "Rechazado", IF(L6="Concluido", "Concluido", IF(AND(L6="En Proceso", TODAY()<=WORKDAY(B6,15)), "En Tiempo", IF(L6="En Proceso", "Atrasado", "")))) -> Atrasado | D6: Federal | E6: Secretaría de la Contraloría | F6: Coordinación Administrativa (21800005000000S) | G6: 2000 Materiales y Suministros | H6: 2300 – Materias Primas y Materiales de Producción y Comercialización | I6: 2381 Mercancías para su comercialización en tiendas del sector público | J6: =IF(O6="","", IFERROR( IF(VALUE(SUBSTITUTE(SUBSTITUTE(TRIM(O6),"$",""),",",""))<=0,"", IF(VALUE(SUBSTITUTE(SUBSTITUTE(TRIM(O6),"$",""),",",""))<=580000,"CP", IF(VALUE(SUBSTITUTE(SUBSTITUTE(TRIM(O6),"$",""),",",""))<=1740000,"IRP","LPNP"))), "")) -> CP | L6: En Proceso | M6: =IFERROR(IF(OR(VLOOKUP(A6,Adjudicacion!A:N,14,0)=0, VLOOKUP(A6,Adjudicacion!A:N,14,0)=""), L6, VLOOKUP(A6,Adjudicacion!A:N,14,0)), L6) -> En Proceso | N6: Bien- Adquisición de materiales y suministros | O6: 120770 | P6: ADQUISICIÓN DE MATERIALES, BIENES E INSUMOS REQUERIDOS POR EL LABORATORIO DE ANÁLISIS Y VERIFICACIÓN DE CLIDAD DE MATERIALES DE CONSTRUCCIÓN | Q6: NO
A7: F-0005-2026 | B7: 46149 | C7: =IF(L7="Rechazado", "Rechazado", IF(L7="Concluido", "Concluido", IF(AND(L7="En Proceso", TODAY()<=WORKDAY(B7,15)), "En Tiempo", IF(L7="En Proceso", "Atrasado", "")))) -> Atrasado | D7: Federal | E7: Secretaría de la Contraloría | F7: Coordinación Administrativa (21800005000000S) | G7: 3000 Servicios generales | H7: 3500 – Servicios de Instalación, Reparación, Mantenimiento y Conservación | I7: 3571 Reparación, instalación y mantenimiento de maquinaria, equipo industrial y diverso | J7: =IF(O7="","", IFERROR( IF(VALUE(SUBSTITUTE(SUBSTITUTE(TRIM(O7),"$",""),",",""))<=0,"", IF(VALUE(SUBSTITUTE(SUBSTITUTE(TRIM(O7),"$",""),",",""))<=580000,"CP", IF(VALUE(SUBSTITUTE(SUBSTITUTE(TRIM(O7),"$",""),",",""))<=1740000,"IRP","LPNP"))), "")) -> CP | L7: En Proceso | M7: =IFERROR(IF(OR(VLOOKUP(A7,Adjudicacion!A:N,14,0)=0, VLOOKUP(A7,Adjudicacion!A:N,14,0)=""), L7, VLOOKUP(A7,Adjudicacion!A:N,14,0)), L7) -> En Proceso | N7: Servicio- Contratacion de servicios generales | O7: 80800 | P7: SERVICIO DE CALIBRACIÓN A LOS EQUIPOS ESPECIALIZADOS DEL LABORATORIO DE ANÁLISIS Y VERIFICACIÓN DE CALIDAD DE MATERIALES DE CONSTRUCCIÓN | Q7: NO
A8: F-0006-2026 | B8: 46149 | C8: =IF(L8="Rechazado", "Rechazado", IF(L8="Concluido", "Concluido", IF(AND(L8="En Proceso", TODAY()<=WORKDAY(B8,15)), "En Tiempo", IF(L8="En Proceso", "Atrasado", "")))) -> Atrasado | D8: Federal | E8: Secretaría de la Contraloría | F8: Coordinación Administrativa (21800005000000S) | G8: 3000 Servicios generales | H8: 3500 – Servicios de Instalación, Reparación, Mantenimiento y Conservación | I8: 3571 Reparación, instalación y mantenimiento de maquinaria, equipo industrial y diverso | J8: =IF(O8="","", IFERROR( IF(VALUE(SUBSTITUTE(SUBSTITUTE(TRIM(O8),"$",""),",",""))<=0,"", IF(VALUE(SUBSTITUTE(SUBSTITUTE(TRIM(O8),"$",""),",",""))<=580000,"CP", IF(VALUE(SUBSTITUTE(SUBSTITUTE(TRIM(O8),"$",""),",",""))<=1740000,"IRP","LPNP"))), "")) -> CP | L8: En Proceso | M8: =IFERROR(IF(OR(VLOOKUP(A8,Adjudicacion!A:N,14,0)=0, VLOOKUP(A8,Adjudicacion!A:N,14,0)=""), L8, VLOOKUP(A8,Adjudicacion!A:N,14,0)), L8) -> En Proceso | N8: Servicio- Contratacion de servicios generales | O8: 178100 | P8: SERVICIO DE MANTENIMIENTO A LOS EQUIPOS ESPECIALIZADOS DEL LABORATORIO DE ANÁLISIS Y VERIFICACIÓN DE CALIDAD DE MATERIALES DE CONSTRUCCIÓN | Q8: NO
A9: F-0007-2026 | B9: 46150 | C9: =IF(L9="Rechazado", "Rechazado", IF(L9="Concluido", "Concluido", IF(AND(L9="En Proceso", TODAY()<=WORKDAY(B9,15)), "En Tiempo", IF(L9="En Proceso", "Atrasado", "")))) -> Rechazado | D9: Federal | E9: Consejería Jurídica | F9: Coordinación Administrativa (23300001000000S) | G9: 5000 Bienes muebles inmuebles e intangibles | H9: 5600 – Maquinaria, Otros Equipos y Herramientas | I9: 5631 Maquinaria y equipo de construcción | J9: =IF(O9="","", IFERROR( IF(VALUE(SUBSTITUTE(SUBSTITUTE(TRIM(O9),"$",""),",",""))<=0,"", IF(VALUE(SUBSTITUTE(SUBSTITUTE(TRIM(O9),"$",""),",",""))<=580000,"CP", IF(VALUE(SUBSTITUTE(SUBSTITUTE(TRIM(O9),"$",""),",",""))<=1740000,"IRP","LPNP"))), "")) -> LPNP | L9: Rechazado | M9: =IFERROR(IF(OR(VLOOKUP(A9,Adjudicacion!A:N,14,0)=0, VLOOKUP(A9,Adjudicacion!A:N,14,0)=""), L9, VLOOKUP(A9,Adjudicacion!A:N,14,0)), L9) -> Rechazado | N9: Bien- Adquisición de materiales y suministros | O9: 4120000 | P9: ADQUISICIÓN DE MAQUINARIA Y EQUIPO DE CONSTRUCCIÓN (MINICARGADOR) | Q9: NO
A10: S001 | B10: 46029 | C10: =IF(L10="Rechazado", "Rechazado", IF(L10="Concluido", "Concluido", IF(AND(L10="En Proceso", TODAY()<=WORKDAY(B10,15)), "En Tiempo", IF(L10="En Proceso", "Atrasado", "")))) -> Concluido | D10: Estatal | E10: Consejería Jurídica | F10: Coordinación Administrativa (23300001000000S) | G10: 3000 Servicios generales | H10: 3800 – Servicios Oficiales | I10: 3821 Gastos de ceremonias oficiales y de orden social | J10: =IF(O10="","", IFERROR( IF(VALUE(SUBSTITUTE(SUBSTITUTE(TRIM(O10),"$",""),",",""))<=0,"", IF(VALUE(SUBSTITUTE(SUBSTITUTE(TRIM(O10),"$",""),",",""))<=580000,"CP", IF(VALUE(SUBSTITUTE(SUBSTITUTE(TRIM(O10),"$",""),",",""))<=1740000,"IRP","LPNP"))), "")) -> LPNP | K10: 2,257,873.33 | L10: Concluido | M10: =IFERROR(IF(OR(VLOOKUP(A10,Adjudicacion!A:N,14,0)=0, VLOOKUP(A10,Adjudicacion!A:N,14,0)=""), L10, VLOOKUP(A10,Adjudicacion!A:N,14,0)), L10) -> Adjudicado | N10: Servicio- Contratacion de servicios generales | O10: 61641216 | P10: CARAVANAS ITINERANTES POR LA JUSTICIA SOCIAL | Q10: SI | R10: 78940488 | S10: 78940488 | T10: 78940488 | U10: 50234856
A11: S002 | B11: 46030 | C11: =IF(L11="Rechazado", "Rechazado", IF(L11="Concluido", "Concluido", IF(AND(L11="En Proceso", TODAY()<=WORKDAY(B11,15)), "En Tiempo", IF(L11="En Proceso", "Atrasado", "")))) -> Concluido | D11: Estatal | E11: Consejería Jurídica | F11: Coordinación Administrativa (23300001000000S) | G11: 3000 Servicios generales | H11: 3700 – Servicios de Traslado y Viáticos | I11: 3791 Otros servicios de traslado y hospedaje | J11: =IF(O11="","", IFERROR( IF(VALUE(SUBSTITUTE(SUBSTITUTE(TRIM(O11),"$",""),",",""))<=0,"", IF(VALUE(SUBSTITUTE(SUBSTITUTE(TRIM(O11),"$",""),",",""))<=580000,"CP", IF(VALUE(SUBSTITUTE(SUBSTITUTE(TRIM(O11),"$",""),",",""))<=1740000,"IRP","LPNP"))), "")) | K11: 1,003.27 | L11: Concluido | M11: =IFERROR(IF(OR(VLOOKUP(A11,Adjudicacion!A:N,14,0)=0, VLOOKUP(A11,Adjudicacion!A:N,14,0)=""), L11, VLOOKUP(A11,Adjudicacion!A:N,14,0)), L11) -> Concluido | N11: Servicio- Contratacion de servicios generales | O11: 0 | P11: SERVICIO DE ESTACIONAMIENTO PARA LA CONSEJERÍA JURÍDICA | Q11: NO
A12: S003 | B12: 46031 | C12: =IF(L12="Rechazado", "Rechazado", IF(L12="Concluido", "Concluido", IF(AND(L12="En Proceso", TODAY()<=WORKDAY(B12,15)), "En Tiempo", IF(L12="En Proceso", "Atrasado", "")))) -> Rechazado | D12: Estatal | E12: Secretaría del Agua | F12: Coordinación Administrativa (23200002000000S) | G12: 5000 Bienes muebles inmuebles e intangibles | H12: 5100 – Mobiliario y Equipo de Administración | I12: 5111 Muebles y Enceres | J12: =IF(O12="","", IFERROR( IF(VALUE(SUBSTITUTE(SUBSTITUTE(TRIM(O12),"$",""),",",""))<=0,"", IF(VALUE(SUBSTITUTE(SUBSTITUTE(TRIM(O12),"$",""),",",""))<=580000,"CP", IF(VALUE(SUBSTITUTE(SUBSTITUTE(TRIM(O12),"$",""),",",""))<=1740000,"IRP","LPNP"))), "")) -> IRP | K12: 0 | L12: Rechazado | M12: =IFERROR(IF(OR(VLOOKUP(A12,Adjudicacion!A:N,14,0)=0, VLOOKUP(A12,Adjudicacion!A:N,14,0)=""), L12, VLOOKUP(A12,Adjudicacion!A:N,14,0)), L12) -> Rechazado | N12: Bien- Adquisición de materiales y suministros | O12: 1500000 | P12: ARCHIVERO ESCRITORIO EJECUTIVO ESCRITORIO OPERATIVO SILLA EJECUTIVA SILLA SECRETARIAL ARCHIVERO ANAQUELES LIBRERO MESA OPERATIVA MESA DE TRABAJO MESA DE JUNTAS DISPENSADOR DE AGUA PERCHERO | Q12: NO
A13: S004 | B13: 46032 | C13: =IF(L13="Rechazado", "Rechazado", IF(L13="Concluido", "Concluido", IF(AND(L13="En Proceso", TODAY()<=WORKDAY(B13,15)), "En Tiempo", IF(L13="En Proceso", "Atrasado", "")))) -> Rechazado | D13: Estatal | E13: Secretaría del Agua | F13: Coordinación Administrativa (23200002000000S) | G13: 4000 Transferencias asignaciones subsidios y otras ayudas | H13: 4200 – Transferencias al Resto del Sector Público | I13: 4242 Donativos a municipios | J13: =IF(O13="","", IFERROR( IF(VALUE(SUBSTITUTE(SUBSTITUTE(TRIM(O13),"$",""),",",""))<=0,"", IF(VALUE(SUBSTITUTE(SUBSTITUTE(TRIM(O13),"$",""),",",""))<=580000,"CP", IF(VALUE(SUBSTITUTE(SUBSTITUTE(TRIM(O13),"$",""),",",""))<=1740000,"IRP","LPNP"))), "")) | K13: 0 | L13: Rechazado | M13: =IFERROR(IF(OR(VLOOKUP(A13,Adjudicacion!A:N,14,0)=0, VLOOKUP(A13,Adjudicacion!A:N,14,0)=""), L13, VLOOKUP(A13,Adjudicacion!A:N,14,0)), L13) -> Rechazado | N13: Bien- Adquisición de materiales y suministros | O13: 0 | P13: TUBERÍA DE 50.8 MILÍMETROS PARA EL PROGRAMA EMERGENTE PARA MEJORA DE INFRAESTRUCTURA EN REDES DE DISTRIBUCIÓN TUBERÍA DE 101.6 MILÍMETROS PARA EL PROGRAMA EMERGENTE PARA MEJORA DE INFRAESTRUCTURA EN REDES DE DISTRIBUCIÓN TUBERÍA DE 152.4 MILÍMETROS PARA EL PROGRAMA EMERGENTE PARA MEJORA DE INFRAESTRUCTURA EN REDES DE DISTRIBUCIÓN | Q13: NO
A14: S005 | B14: 46033 | C14: =IF(L14="Rechazado", "Rechazado", IF(L14="Concluido", "Concluido", IF(AND(L14="En Proceso", TODAY()<=WORKDAY(B14,15)), "En Tiempo", IF(L14="En Proceso", "Atrasado", "")))) -> Rechazado | D14: Estatal | E14: Secretaría del Agua | F14: Coordinación Administrativa (23200002000000S) | G14: 4000 Transferencias asignaciones subsidios y otras ayudas | H14: 4200 – Transferencias al Resto del Sector Público | I14: 4242 Donativos a municipios | J14: =IF(O14="","", IFERROR( IF(VALUE(SUBSTITUTE(SUBSTITUTE(TRIM(O14),"$",""),",",""))<=0,"", IF(VALUE(SUBSTITUTE(SUBSTITUTE(TRIM(O14),"$",""),",",""))<=580000,"CP", IF(VALUE(SUBSTITUTE(SUBSTITUTE(TRIM(O14),"$",""),",",""))<=1740000,"IRP","LPNP"))), "")) | K14: 0 | L14: Rechazado | M14: =IFERROR(IF(OR(VLOOKUP(A14,Adjudicacion!A:N,14,0)=0, VLOOKUP(A14,Adjudicacion!A:N,14,0)=""), L14, VLOOKUP(A14,Adjudicacion!A:N,14,0)), L14) -> Rechazado | N14: Bien- Adquisición de materiales y suministros | O14: 0 | P14: PAQUETE 1 INSTALACIÓN Y PUESTA EN MARCHA DE SISTEMAS DE CAPTADORES DE AGUA EN ESPACIÓS PÚBLICOS PAQUETE 2 INSTALACIÓN Y PUESTA EN MARCHA DE SISTEMAS DE CAPTADORES DE AGUA EN ESPACIÓS PÚBLICOS PAQUETE 3 INSTALACIÓN Y PUESTA EN MARCHA DE SISTEMAS DE CAPTADORES DE AGUA EN ESPACIÓS PÚBLICOS | Q14: NO
A15: S006 | B15: 46034 | C15: =IF(L15="Rechazado", "Rechazado", IF(L15="Concluido", "Concluido", IF(AND(L15="En Proceso", TODAY()<=WORKDAY(B15,15)), "En Tiempo", IF(L15="En Proceso", "Atrasado", "")))) -> Rechazado | D15: Estatal | E15: Secretaría del Agua | F15: Coordinación Administrativa (23200002000000S) | G15: 2000 Materiales y Suministros | H15: 2400 – Materiales y Artículos de Construcción y de Reparación | I15: 2411 Productos minerales no metálicos | J15: =IF(O15="","", IFERROR( IF(VALUE(SUBSTITUTE(SUBSTITUTE(TRIM(O15),"$",""),",",""))<=0,"", IF(VALUE(SUBSTITUTE(SUBSTITUTE(TRIM(O15),"$",""),",",""))<=580000,"CP", IF(VALUE(SUBSTITUTE(SUBSTITUTE(TRIM(O15),"$",""),",",""))<=1740000,"IRP","LPNP"))), "")) | K15: 0 | L15: Rechazado | M15: =IFERROR(IF(OR(VLOOKUP(A15,Adjudicacion!A:N,14,0)=0, VLOOKUP(A15,Adjudicacion!A:N,14,0)=""), L15, VLOOKUP(A15,Adjudicacion!A:N,14,0)), L15) -> Rechazado | N15: Bien- Adquisición de materiales y suministros | O15: 0 | P15: PROGRAMA DE BAÑOS ECOLÓGICOS | Q15: NO
A16: S007 | B16: 46035 | C16: =IF(L16="Rechazado", "Rechazado", IF(L16="Concluido", "Concluido", IF(AND(L16="En Proceso", TODAY()<=WORKDAY(B16,15)), "En Tiempo", IF(L16="En Proceso", "Atrasado", "")))) -> Concluido | D16: Estatal | E16: Organismos OPDS | F16: Sistema para el Desarrollo Integral de la Familia del Estado de México 200C01000000000 | G16: 4000 Transferencias asignaciones subsidios y otras ayudas | H16: 4400 – Ayudas Sociales | I16: 4412 Despensas | J16: =IF(O16="","", IFERROR( IF(VALUE(SUBSTITUTE(SUBSTITUTE(TRIM(O16),"$",""),",",""))<=0,"", IF(VALUE(SUBSTITUTE(SUBSTITUTE(TRIM(O16),"$",""),",",""))<=580000,"CP", IF(VALUE(SUBSTITUTE(SUBSTITUTE(TRIM(O16),"$",""),",",""))<=1740000,"IRP","LPNP"))), "")) -> LPNP | K16: 2,302,790,324.14 | L16: Concluido | M16: =IFERROR(IF(OR(VLOOKUP(A16,Adjudicacion!A:N,14,0)=0, VLOOKUP(A16,Adjudicacion!A:N,14,0)=""), L16, VLOOKUP(A16,Adjudicacion!A:N,14,0)), L16) -> Adjudicado | N16: Bien- Adquisición de materiales y suministros | O16: 2.3276237e+09 | P16: PAQUETE DE DESAYUNOS ESCOLARES FRÍOS PAQUETE DE ALIMENTOS DE DESAYUNOS ESCOLARES CALIENTES CANASTA DE PRODUCTOS ALIMENTICIOS | Q16: NO
A17: S007-D | B17: 46035 | C17: =IF(L17="Rechazado", "Rechazado", IF(L17="Concluido", "Concluido", IF(AND(L17="En Proceso", TODAY()<=WORKDAY(B17,15)), "En Tiempo", IF(L17="En Proceso", "Atrasado", "")))) -> Concluido | D17: Estatal | E17: Organismos OPDS | F17: Sistema para el Desarrollo Integral de la Familia del Estado de México 200C01000000000 | G17: 4000 Transferencias asignaciones subsidios y otras ayudas | H17: 4400 – Ayudas Sociales | I17: 4412 Despensas | J17: =IF(O17="","", IFERROR( IF(VALUE(SUBSTITUTE(SUBSTITUTE(TRIM(O17),"$",""),",",""))<=0,"", IF(VALUE(SUBSTITUTE(SUBSTITUTE(TRIM(O17),"$",""),",",""))<=580000,"CP", IF(VALUE(SUBSTITUTE(SUBSTITUTE(TRIM(O17),"$",""),",",""))<=1740000,"IRP","LPNP"))), "")) -> LPNP | K17: 2,302,790,324.14 | L17: Concluido | M17: =IFERROR(IF(OR(VLOOKUP(A17,Adjudicacion!A:N,14,0)=0, VLOOKUP(A17,Adjudicacion!A:N,14,0)=""), L17, VLOOKUP(A17,Adjudicacion!A:N,14,0)), L17) -> Desierta | N17: Bien- Adquisición de materiales y suministros | O17: 2.3276237e+09 | P17: PAQUETE DE DESAYUNOS ESCOLARES FRÍOS PAQUETE DE ALIMENTOS DE DESAYUNOS ESCOLARES CALIENTES CANASTA DE PRODUCTOS ALIMENTICIOS | Q17: NO
A18: S008 | B18: 46036 | C18: =IF(L18="Rechazado", "Rechazado", IF(L18="Concluido", "Concluido", IF(AND(L18="En Proceso", TODAY()<=WORKDAY(B18,15)), "En Tiempo", IF(L18="En Proceso", "Atrasado", "")))) -> Concluido | D18: Estatal | E18: Secretaría de Seguridad | F18: Coordinación Administrativa | G18: 3000 Servicios generales | H18: 3100 – Servicios Básicos | I18: 3191 Servicios de telecomunicación especializados | J18: =IF(O18="","", IFERROR( IF(VALUE(SUBSTITUTE(SUBSTITUTE(TRIM(O18),"$",""),",",""))<=0,"", IF(VALUE(SUBSTITUTE(SUBSTITUTE(TRIM(O18),"$",""),",",""))<=580000,"CP", IF(VALUE(SUBSTITUTE(SUBSTITUTE(TRIM(O18),"$",""),",",""))<=1740000,"IRP","LPNP"))), "")) -> LPNP | K18: 331,113,054.70 | L18: Concluido | M18: =IFERROR(IF(OR(VLOOKUP(A18,Adjudicacion!A:N,14,0)=0, VLOOKUP(A18,Adjudicacion!A:N,14,0)=""), L18, VLOOKUP(A18,Adjudicacion!A:N,14,0)), L18) -> Adjudicado | N18: Servicio- Contratacion de servicios generales | O18: 3.4135366e+08 | P18: SISTEMA INTEGRAL DE DISPOSITIVOS DE MONITOREO ELECTRONICO (BRAZALETES) | Q18: NO
A19: S009 | B19: 46037 | C19: =IF(L19="Rechazado", "Rechazado", IF(L19="Concluido", "Concluido", IF(AND(L19="En Proceso", TODAY()<=WORKDAY(B19,15)), "En Tiempo", IF(L19="En Proceso", "Atrasado", "")))) -> Concluido | D19: Estatal | E19: Secretaría de Seguridad | F19: Coordinación Administrativa | G19: 3000 Servicios generales | H19: 3500 – Servicios de Instalación, Reparación, Mantenimiento y Conservación | I19: 3581 Servicios de lavandería, limpieza e higiene | J19: =IF(O19="","", IFERROR( IF(VALUE(SUBSTITUTE(SUBSTITUTE(TRIM(O19),"$",""),",",""))<=0,"", IF(VALUE(SUBSTITUTE(SUBSTITUTE(TRIM(O19),"$",""),",",""))<=580000,"CP", IF(VALUE(SUBSTITUTE(SUBSTITUTE(TRIM(O19),"$",""),",",""))<=1740000,"IRP","LPNP"))), "")) -> LPNP | K19: 613,312,275.00 | L19: Concluido | M19: =IFERROR(IF(OR(VLOOKUP(A19,Adjudicacion!A:N,14,0)=0, VLOOKUP(A19,Adjudicacion!A:N,14,0)=""), L19, VLOOKUP(A19,Adjudicacion!A:N,14,0)), L19) -> Adjudicado | N19: Servicio- Contratacion de servicios generales | O19: 613312275 | P19: SERVICIO INTEGRAL DE LAVANDERIA, LIMPIEZA, DESINFECCION E HIGIENE | Q19: NO
A20: S010 | B20: 46038 | C20: =IF(L20="Rechazado", "Rechazado", IF(L20="Concluido", "Concluido", IF(AND(L20="En Proceso", TODAY()<=WORKDAY(B20,15)), "En Tiempo", IF(L20="En Proceso", "Atrasado", "")))) -> Concluido | D20: Estatal | E20: Secretaría de Seguridad | F20: Coordinación Administrativa | G20: 2000 Materiales y Suministros | H20: 2200 – Alimentos y Utensilios | I20: 2211 Productos alimenticios para personas | J20: =IF(O20="","", IFERROR( IF(VALUE(SUBSTITUTE(SUBSTITUTE(TRIM(O20),"$",""),",",""))<=0,"", IF(VALUE(SUBSTITUTE(SUBSTITUTE(TRIM(O20),"$",""),",",""))<=580000,"CP", IF(VALUE(SUBSTITUTE(SUBSTITUTE(TRIM(O20),"$",""),",",""))<=1740000,"IRP","LPNP"))), "")) -> LPNP | K20: 1,347,366,262.84 | L20: Concluido | M20: =IFERROR(IF(OR(VLOOKUP(A20,Adjudicacion!A:N,14,0)=0, VLOOKUP(A20,Adjudicacion!A:N,14,0)=""), L20, VLOOKUP(A20,Adjudicacion!A:N,14,0)), L20) -> Adjudicado | N20: Bien- Adquisición de materiales y suministros | O20: 1.3473663e+09 | P20: SUMINISTRO DE VIVERES Y ALIMENTOS PARA CONSUMO HUMANO | Q20: NO
